<?xml version="1.0"?>

<robot name="rr-arm">
	
	<link name="base_link"/>

	<link name="link_0">
		<visual>
			<geometry>
				<box size="1 .1 .1"/>
			</geometry>
			<origin rpy="0 0 0" xyz="0.5 0 0"/>
		</visual>
	</link>

	<joint name="joint0" type="revolute">
		<axis rpy="0 0 0" xyz="0 0 1"/>
		<parent link="base_link"/>
		<child link="link_0"/>
        <limit lower="0.0" upper="6.28" effort="300.0" velocity="1.0"/>
	</joint>

	<link name="link_1">
		<visual>
			<geometry>
				<box size="1 .05 .05"/>
			</geometry>
			<origin rpy="0 0 0" xyz="0.5 0 0"/>
		</visual>
	</link>

	<joint name="joint1" type="revolute">
		<axis rpy="0 0 0" xyz="0 0 1"/>
		<parent link="link_0"/>
		<child link="link_1"/>
		<origin rpy="0 0 0" xyz="1 0 0"/>
        <limit lower="0.0" upper="6.28" effort="300.0" velocity="1.0"/>
	</joint>

	<link name="tool0"/>

	<joint name="joint_ef" type="fixed">
		<parent link="link_1"/>
		<child link="tool0"/>
		<origin rpy="0 0 0" xyz="1 0 0"/>
	</joint>

</robot>